{"name":"doNotAllowUsersToLogin","status":"failed","statusDetails":{"known":false,"muted":false,"flaky":false,"message":"expected [false] but found [true]","trace":"java.lang.AssertionError: expected [false] but found [true]\n\tat org.testng.Assert.fail(Assert.java:99)\n\tat org.testng.Assert.failNotEquals(Assert.java:1037)\n\tat org.testng.Assert.assertEqualsImpl(Assert.java:140)\n\tat org.testng.Assert.assertEquals(Assert.java:122)\n\tat org.testng.Assert.assertEquals(Assert.java:819)\n\tat org.testng.Assert.assertEquals(Assert.java:829)\n\tat Tests.LoginTest.doNotAllowUsersToLogin(LoginTest.java:61)\n\tat java.base/jdk.internal.reflect.NativeMethodAccessorImpl.invoke0(Native Method)\n\tat java.base/jdk.internal.reflect.NativeMethodAccessorImpl.invoke(NativeMethodAccessorImpl.java:62)\n\tat java.base/jdk.internal.reflect.DelegatingMethodAccessorImpl.invoke(DelegatingMethodAccessorImpl.java:43)\n\tat java.base/java.lang.reflect.Method.invoke(Method.java:567)\n\tat org.testng.internal.MethodInvocationHelper.invokeMethod(MethodInvocationHelper.java:132)\n\tat org.testng.internal.TestInvoker.invokeMethod(TestInvoker.java:599)\n\tat org.testng.internal.TestInvoker.invokeTestMethod(TestInvoker.java:174)\n\tat org.testng.internal.MethodRunner.runInSequence(MethodRunner.java:46)\n\tat org.testng.internal.TestInvoker$MethodInvocationAgent.invoke(TestInvoker.java:822)\n\tat org.testng.internal.TestInvoker.invokeTestMethods(TestInvoker.java:147)\n\tat org.testng.internal.TestMethodWorker.invokeTestMethods(TestMethodWorker.java:146)\n\tat org.testng.internal.TestMethodWorker.run(TestMethodWorker.java:128)\n\tat java.base/java.util.ArrayList.forEach(ArrayList.java:1507)\n\tat org.testng.TestRunner.privateRun(TestRunner.java:764)\n\tat org.testng.TestRunner.run(TestRunner.java:585)\n\tat org.testng.SuiteRunner.runTest(SuiteRunner.java:384)\n\tat org.testng.SuiteRunner.runSequentially(SuiteRunner.java:378)\n\tat org.testng.SuiteRunner.privateRun(SuiteRunner.java:337)\n\tat org.testng.SuiteRunner.run(SuiteRunner.java:286)\n\tat org.testng.SuiteRunnerWorker.runSuite(SuiteRunnerWorker.java:53)\n\tat org.testng.SuiteRunnerWorker.run(SuiteRunnerWorker.java:96)\n\tat org.testng.TestNG.runSuitesSequentially(TestNG.java:1218)\n\tat org.testng.TestNG.runSuitesLocally(TestNG.java:1140)\n\tat org.testng.TestNG.runSuites(TestNG.java:1069)\n\tat org.testng.TestNG.run(TestNG.java:1037)\n\tat org.apache.maven.surefire.testng.TestNGExecutor.run(TestNGExecutor.java:283)\n\tat org.apache.maven.surefire.testng.TestNGXmlTestSuite.execute(TestNGXmlTestSuite.java:75)\n\tat org.apache.maven.surefire.testng.TestNGProvider.invoke(TestNGProvider.java:120)\n\tat org.apache.maven.surefire.booter.ForkedBooter.invokeProviderInSameClassLoader(ForkedBooter.java:383)\n\tat org.apache.maven.surefire.booter.ForkedBooter.runSuitesInProcess(ForkedBooter.java:344)\n\tat org.apache.maven.surefire.booter.ForkedBooter.execute(ForkedBooter.java:125)\n\tat org.apache.maven.surefire.booter.ForkedBooter.main(ForkedBooter.java:417)\n"},"stage":"finished","description":"User with wrong credentials is not able to login and warning message is displayed","steps":[],"attachments":[],"parameters":[{"name":"arg0","value":"pojo.loginData@fcf9525"}],"start":1603403379618,"stop":1603403382241,"uuid":"bf39bddb-5c8e-4ae3-af14-c26ae16a1849","historyId":"d1025c5a600777a1918423e28b1a976a","fullName":"Tests.LoginTest.doNotAllowUsersToLogin","labels":[{"name":"package","value":"Tests.LoginTest"},{"name":"testClass","value":"Tests.LoginTest"},{"name":"testMethod","value":"doNotAllowUsersToLogin"},{"name":"parentSuite","value":"Login Suite"},{"name":"suite","value":"login Test"},{"name":"subSuite","value":"Tests.LoginTest"},{"name":"host","value":"Alexanders-MacBook-Pro.local"},{"name":"thread","value":"6802@Alexanders-MacBook-Pro.local.main(1)"},{"name":"framework","value":"testng"},{"name":"language","value":"java"}],"links":[{"name":"https://example.org","type":"custom"}]}